<?xml version="1.0" encoding="UTF-8"?>
<testng-results ignored="1" total="2" passed="0" failed="1" skipped="0">
  <reporter-output>
  </reporter-output>
  <suite started-at="2018-06-11T22:50:49Z" name="Failed suite [Failed suite [Default suite]]" finished-at="2018-06-11T22:50:49Z" duration-ms="31">
    <groups>
    </groups>
    <test started-at="2018-06-11T22:50:49Z" name="Default test(failed)(failed)" finished-at="2018-06-11T22:50:49Z" duration-ms="31">
      <class name="automationFramework.EjecutaPrueba">
        <test-method signature="case2()[pri:2, instance:automationFramework.EjecutaPrueba@55f616cf]" started-at="2018-06-11T22:50:49Z" name="case2" description="este es un segundo caso vacio" finished-at="2018-06-11T22:50:49Z" duration-ms="0" status="FAIL">
          <exception class="java.lang.AssertionError">
            <message>
              <![CDATA[expected:<11> but was:<12>]]>
            </message>
            <full-stacktrace>
              <![CDATA[java.lang.AssertionError: expected:<11> but was:<12>
at org.testng.AssertJUnit.fail(AssertJUnit.java:59)
at org.testng.AssertJUnit.failNotEquals(AssertJUnit.java:364)
at org.testng.AssertJUnit.assertEquals(AssertJUnit.java:80)
at org.testng.AssertJUnit.assertEquals(AssertJUnit.java:245)
at org.testng.AssertJUnit.assertEquals(AssertJUnit.java:252)
at automationFramework.EjecutaPrueba.case2(EjecutaPrueba.java:105)
at java.base/jdk.internal.reflect.NativeMethodAccessorImpl.invoke0(Native Method)
at java.base/jdk.internal.reflect.NativeMethodAccessorImpl.invoke(Unknown Source)
at java.base/jdk.internal.reflect.DelegatingMethodAccessorImpl.invoke(Unknown Source)
at java.base/java.lang.reflect.Method.invoke(Unknown Source)
at org.testng.internal.MethodInvocationHelper.invokeMethod(MethodInvocationHelper.java:124)
at org.testng.internal.Invoker.invokeMethod(Invoker.java:580)
at org.testng.internal.Invoker.invokeTestMethod(Invoker.java:716)
at org.testng.internal.Invoker.invokeTestMethods(Invoker.java:988)
at org.testng.internal.TestMethodWorker.invokeTestMethods(TestMethodWorker.java:125)
at org.testng.internal.TestMethodWorker.run(TestMethodWorker.java:109)
at org.testng.TestRunner.privateRun(TestRunner.java:648)
at org.testng.TestRunner.run(TestRunner.java:505)
at org.testng.SuiteRunner.runTest(SuiteRunner.java:455)
at org.testng.SuiteRunner.runSequentially(SuiteRunner.java:450)
at org.testng.SuiteRunner.privateRun(SuiteRunner.java:415)
at org.testng.SuiteRunner.run(SuiteRunner.java:364)
at org.testng.SuiteRunnerWorker.runSuite(SuiteRunnerWorker.java:52)
at org.testng.SuiteRunnerWorker.run(SuiteRunnerWorker.java:84)
at org.testng.TestNG.runSuitesSequentially(TestNG.java:1208)
at org.testng.TestNG.runSuitesLocally(TestNG.java:1137)
at org.testng.TestNG.runSuites(TestNG.java:1049)
at org.testng.TestNG.run(TestNG.java:1017)
at org.testng.remote.AbstractRemoteTestNG.run(AbstractRemoteTestNG.java:114)
at org.testng.remote.RemoteTestNG.initAndRun(RemoteTestNG.java:251)
at org.testng.remote.RemoteTestNG.main(RemoteTestNG.java:77)
]]>
            </full-stacktrace>
          </exception> <!-- java.lang.AssertionError -->
          <reporter-output>
          </reporter-output>
        </test-method> <!-- case2 -->
      </class> <!-- automationFramework.EjecutaPrueba -->
    </test> <!-- Default test(failed)(failed) -->
  </suite> <!-- Failed suite [Failed suite [Default suite]] -->
</testng-results>
